<?xml version="1.0" ?>
<!-- =================================================================================== -->
<!-- |    This document was autogenerated by xacro from robot.urdf.xacro               | -->
<!-- |    EDITING THIS FILE BY HAND IS NOT RECOMMENDED                                 | -->
<!-- =================================================================================== -->
<robot name="robot">
  <!-- Specify some standard inertial calculations https://en.wikipedia.org/wiki/List_of_moments_of_inertia -->
  <!-- These make use of xacro's mathematical functionality -->
  <material name="white">
    <color rgba="1 1 1 1"/>
  </material>
  <material name="orange">
    <color rgba="1 0.3 0.1 1"/>
  </material>
  <material name="blue">
    <color rgba="0.2 0.2 1 1"/>
  </material>
  <material name="black">
    <color rgba="0 0 0 1"/>
  </material>
  <!-- BASE LINK -->
  <!--
  link name="base_link">

    </link>
   CHASSIS LINK
  <joint name="base_plate_joint" type="fixed">
    <parent link="base_link"/>
    <child link="base_plate"/>
    <origin xyz="0 0 0.25"/>
  </joint>
  -->
  <link name="base_plate">
    <visual>
      <origin xyz="0 0 0"/>
      <geometry>
        <box size="0.25 0.15 0.05"/>
      </geometry>
      <material name="white"/>
    </visual>
    
    <inertial>
      <origin rpy="0 0 0" xyz="0 0 0"/>
      <mass value="1.0"/>
      <inertia ixx="0.0020833333333333333" ixy="0.0" ixz="0.0" iyy="0.005416666666666667" iyz="0.0" izz="0.007083333333333332"/>
    </inertial>
  </link>
  
  
  <!-- STEERING SHAFT LINK -->
  <joint name="steering_shaft_joint" type="revolute">
    <parent link="base_plate"/>
    <child link="steering_shaft"/>
    <origin rpy="0 0 0" xyz="0 0 -0.025"/>
    <axis xyz="0 0 1"/>
    <limit lower="-1.5707963267948966" upper="1.5707963267948966" effort="10" velocity="1.5707963267948966"/>
  </joint>
  <link name="steering_shaft">
    <visual>
      <origin xyz="0 0 -0.0625"/>
      <geometry>
        <cylinder length="0.125" radius="0.025"/>
      </geometry>
      <material name="blue"/>
    </visual>
    <inertial>
      <origin rpy="0 0 0" xyz="0 0 0"/>
      <mass value="0.5"/>
      <inertia ixx="0.0007291666666666667" ixy="0.0" ixz="0.0" iyy="0.0007291666666666667" iyz="0.0" izz="0.00015625000000000003"/>
    </inertial>
  </link>
  
  
  <!-- STEERING WHEEL LINK -->
  <joint name="steering_wheel_joint" type="continuous">
    <parent link="steering_shaft"/>
    <child link="steering_wheel"/>
    <origin rpy="0 1.5707963267948966 0" xyz="0 0 -0.125"/>
    <axis xyz="0 0 1"/>
  </joint>
  <link name="steering_wheel">
    <visual>
      <geometry>
        <cylinder length="0.04" radius="0.1"/>
      </geometry>
      <material name="blue"/>
    </visual>
    <collision>
      <geometry>
        <cylinder length="0.04" radius="0.1"/>
      </geometry>
    </collision>
    <inertial>
      <origin rpy="0 0 0" xyz="0 0 0"/>
      <mass value="3"/>
      <inertia ixx="0.0475" ixy="0.0" ixz="0.0" iyy="0.0475" iyz="0.0" izz="0.09375"/>
    </inertial>
  </link>
  <!-- LINEAR ACTUATOR LINK -->
  <joint name="linear_actuator_joint" type="prismatic">
    <parent link="base_plate"/>
    <child link="linear_actuator"/>
    <origin xyz="0 0 0.025"/>
    <axis xyz="0 0 1"/>
    <limit lower="0" upper="0.12" effort="5000" velocity="0.07"/>
  </joint>
  <link name="linear_actuator">
    <visual>
      <origin xyz="0 0 0.1"/>
      <geometry>
        <box size="0.07 0.15 0.2"/>
      </geometry>
      <material name="black"/>
    </visual>
    <collision>
      <origin xyz="0 0 0.1"/>
      <geometry>
        <box size="0.07 0.15 0.2"/>
      </geometry>
    </collision>
    <inertial>
      <origin rpy="0 0 0" xyz="0 0 0.1"/>
      <mass value="4"/>
      <inertia ixx="0.020833333333333332" ixy="0.0" ixz="0.0" iyy="0.01496666666666667" iyz="0.0" izz="0.009133333333333334"/>
    </inertial>
  </link>
  <!-- FRAME BOX LINK -->
  <joint name="frame_box_joint" type="fixed">
    <parent link="linear_actuator"/>
    <child link="frame_box"/>
    <origin xyz="0 0.18 -0.075"/>
  </joint>
  <link name="frame_box">
    <visual>
      <geometry>
        <box size="0.54 0.15 0.3"/>
      </geometry>
      <material name="black"/>
    </visual>
    <collision>
      <geometry>
        <box size="0.54 0.15 0.3"/>
      </geometry>
    </collision>
    <inertial>
      <origin rpy="0 0 0" xyz="0 0 0"/>
      <mass value="20"/>
      <inertia ixx="0.18749999999999997" ixy="0.0" ixz="0.0" iyy="0.636" iyz="0.0" izz="0.5235000000000001"/>
    </inertial>
  </link>
  <!-- LEFT FORK LINK -->
  <joint name="left_fork_joint" type="fixed">
    <parent link="frame_box"/>
    <child link="left_fork"/>
    <origin xyz="-0.19 0.075 -0.125"/>
  </joint>
  <link name="left_fork">
    <visual>
      <origin xyz="0 0.350 0"/>
      <geometry>
        <box size="0.16 0.7 0.05"/>
      </geometry>
      <material name="black"/>
    </visual>
    <collision>
      <origin xyz="0 0.350 0"/>
      <geometry>
        <box size="0.16 0.7 0.05"/>
      </geometry>
    </collision>
    <inertial>
      <origin rpy="0 0 0" xyz="0 0.575 0"/>
      <mass value="20"/>
      <inertia ixx="0.18749999999999997" ixy="0.0" ixz="0.0" iyy="0.636" iyz="0.0" izz="0.5235000000000001"/>
    </inertial>
  </link>
  <!-- RIGHT FORK LINK -->
  <joint name="right_fork_joint" type="fixed">
    <parent link="frame_box"/>
    <child link="right_fork"/>
    <origin xyz="0.19 0.075 -0.125"/>
  </joint>
  <link name="right_fork">
    <visual>
      <origin xyz="0 0.350 0"/>
      <geometry>
        <box size="0.16 0.7 0.05"/>
      </geometry>
      <material name="black"/>
    </visual>
    <collision>
      <origin xyz="0 0.350 0"/>
      <geometry>
        <box size="0.16 0.7 0.05"/>
      </geometry>
    </collision>
    <inertial>
      <origin rpy="0 0 0" xyz="0 0.350 0"/>
      <mass value="20"/>
      <inertia ixx="0.18749999999999997" ixy="0.0" ixz="0.0" iyy="0.636" iyz="0.0" izz="0.5235000000000001"/>
    </inertial>
  </link>
  
  <!-- FORK WHEEL LEFT LINK -->
  <joint name="fork_wheel_left_joint" type="continuous">
    <parent link="base_plate"/>
    <child link="fork_wheel_left"/>
    <origin rpy="0 1.5707963267948966 0" xyz="-0.19 1.150 -0.2"/>
    <axis xyz="0 0 1"/>
  </joint>
  <link name="fork_wheel_left">
    <visual>
      <geometry>
        <cylinder length="0.1" radius="0.05"/>
      </geometry>
      <material name="blue"/>
    </visual>
    <collision>
      <geometry>
        <cylinder length="0.1" radius="0.05"/>
      </geometry>
    </collision>
    <inertial>
      <origin rpy="0 0 0" xyz="0 0 0"/>
      <mass value="0.3"/>
      <inertia ixx="0.0004375" ixy="0.0" ixz="0.0" iyy="0.0004375" iyz="0.0" izz="0.00037500000000000006"/>
    </inertial>
  </link>
  <!-- FORK WHEEL RIGHT LINK -->
  <joint name="fork_wheel_right_joint" type="continuous">
    <parent link="base_plate"/>
    <child link="fork_wheel_right"/>
    <origin rpy="0 1.5707963267948966 0" xyz="0.19 1.150 -0.2"/>
    <axis xyz="0 0 1"/>
  </joint>
  <link name="fork_wheel_right">
    <visual>
      <geometry>
        <cylinder length="0.1" radius="0.05"/>
      </geometry>
      <material name="blue"/>
    </visual>
    <collision>
      <geometry>
        <cylinder length="0.1" radius="0.05"/>
      </geometry>
    </collision>
    <inertial>
      <origin rpy="0 0 0" xyz="0 0 0"/>
      <mass value="0.3"/>
      <inertia ixx="0.0004375" ixy="0.0" ixz="0.0" iyy="0.0004375" iyz="0.0" izz="0.00037500000000000006"/>
    </inertial>
  </link>
</robot>
