<sdf version='1.7'>
  <world name='default'>
    <light name='sun' type='directional'>
      <cast_shadows>1</cast_shadows>
      <pose>0 0 10 0 -0 0</pose>
      <diffuse>0.8 0.8 0.8 1</diffuse>
      <specular>0.2 0.2 0.2 1</specular>
      <attenuation>
        <range>1000</range>
        <constant>0.9</constant>
        <linear>0.01</linear>
        <quadratic>0.001</quadratic>
      </attenuation>
      <direction>-0.5 0.1 -0.9</direction>
      <spot>
        <inner_angle>0</inner_angle>
        <outer_angle>0</outer_angle>
        <falloff>0</falloff>
      </spot>
    </light>
    <gravity>0 0 -9.8</gravity>
    <magnetic_field>6e-06 2.3e-05 -4.2e-05</magnetic_field>
    <atmosphere type='adiabatic'/>
    <physics type='ode'>
      <max_step_size>0.0001</max_step_size>
      <real_time_factor>1</real_time_factor>
      <real_time_update_rate>10000</real_time_update_rate>
    </physics>
    <scene>
      <ambient>1 1 1 1</ambient>
      <background>0.7 0.7 0.7 1</background>
      <shadows>1</shadows>
    </scene>
    <wind/>
    <spherical_coordinates>
      <surface_model>EARTH_WGS84</surface_model>
      <latitude_deg>0</latitude_deg>
      <longitude_deg>0</longitude_deg>
      <elevation>0</elevation>
      <heading_deg>0</heading_deg>
    </spherical_coordinates>
    <state world_name='default'>
      <sim_time>1318 430700000</sim_time>
      <real_time>16 688294682</real_time>
      <wall_time>1729177027 935707792</wall_time>
      <iterations>72611</iterations>
      <model name='ground_plane'>
        <pose>-5.10672 4.65884 0 0 -0 0</pose>
        <scale>1 1 1</scale>
        <link name='link'>
          <pose>-5.10672 4.65884 0 0 -0 0</pose>
          <velocity>0 0 0 0 -0 0</velocity>
          <acceleration>0 0 0 0 -0 0</acceleration>
          <wrench>0 0 0 0 -0 0</wrench>
        </link>
      </model>
      <model name='my_bot'>
        <pose>0.011847 -0.007295 1.27 4e-06 -8e-06 0.014015</pose>
        <scale>1 1 1</scale>
        <link name='base_link'>
          <pose>0.011847 -0.007295 1.27 4e-06 -8e-06 0.014015</pose>
          <velocity>0.002723 -0.0011 -6.2e-05 -0.003072 -0.000961 0.00204</velocity>
          <acceleration>13.3955 5.11714 124.029 -2.92309 1.10321 -0.453411</acceleration>
          <wrench>26.7911 10.2343 248.058 0 -0 0</wrench>
        </link>
        <link name='fork_wheel_left'>
          <pose>-0.190748 0.889954 1.3025 -1.5706 1.55916 -1.55658</pose>
          <velocity>0.000525 0.008434 0.006317 -0.180903 0.018275 0.071506</velocity>
          <acceleration>5.19398 163.23 198.169 2.81813 -0.155461 0.521806</acceleration>
          <wrench>1.55819 48.9691 59.4506 0 -0 0</wrench>
        </link>
        <link name='fork_wheel_right'>
          <pose>0.189215 0.895274 1.3025 1.57072 1.52005 1.58474</pose>
          <velocity>-0.000741 -0.019652 0.010193 0.604674 -0.022784 -1e-05</velocity>
          <acceleration>-3.03663 -104.507 576.828 0.890996 1.18267 2.26375</acceleration>
          <wrench>-0.910988 -31.352 173.048 0 -0 0</wrench>
        </link>
        <link name='linear_actuator'>
          <pose>0.011845 -0.007296 1.545 -0 -7e-06 0.014015</pose>
          <velocity>0.001992 -0.00046 -0.015994 -0.006188 0.007994 3.7e-05</velocity>
          <acceleration>3.42705 -0.189304 21.4277 2.27881 0.923698 -1.92291</acceleration>
          <wrench>144.964 -8.00757 906.393 0 -0 0</wrench>
        </link>
        <link name='steering_shaft'>
          <pose>0.011845 -0.007296 1.495 4e-06 -8e-06 0.044321</pose>
          <velocity>0.002496 -0.000431 -0.000235 -0.003559 0.004799 0.001259</velocity>
          <acceleration>17.4212 2.84941 121.464 1.9612 -1.12049 -1.98943</acceleration>
          <wrench>8.71062 1.42471 60.7318 0 -0 0</wrench>
        </link>
        <link name='steering_wheel_left'>
          <pose>0.121737 -0.002422 1.37 -1.57065 1.54694 -1.52632</pose>
          <velocity>-0.003803 3.6e-05 0.003838 0.000763 -0.037805 0.005581</velocity>
          <acceleration>-18.0911 0.257736 186.069 0.859401 0.708188 1.93263</acceleration>
          <wrench>-27.1367 0.386604 279.103 0 -0 0</wrench>
        </link>
        <link name='steering_wheel_right'>
          <pose>-0.098045 -0.012169 1.37 -1.65755 1.57066 -1.61323</pose>
          <velocity>0.005936 0.000156 0.011755 -0.000137 0.059752 -0.007081</velocity>
          <acceleration>79.2508 2.59664 217.48 -2.33319 1.47142 -2.8639</acceleration>
          <wrench>118.876 3.89495 326.219 0 -0 0</wrench>
        </link>
      </model>
      <model name='my_model'>
        <pose>4.21367 -1.8557 1 0 -0 0</pose>
        <scale>1 1 1</scale>
        <link name='link'>
          <pose>4.21367 -1.8557 1 0 -0 0</pose>
          <velocity>0 0 0 0 -0 0</velocity>
          <acceleration>0 0 0 0 -0 0</acceleration>
          <wrench>0 0 0 0 -0 0</wrench>
        </link>
      </model>
      <light name='sun'>
        <pose>0 0 10 0 -0 0</pose>
      </light>
    </state>
    <gui fullscreen='0'>
      <camera name='user_camera'>
        <pose>49.4669 -15.7147 37.2956 -0 0.600057 2.84508</pose>
        <view_controller>orbit</view_controller>
        <projection_type>perspective</projection_type>
      </camera>
    </gui>
    <model name='my_model'>
      <static>1</static>
      <link name='link'>
        <visual name='visual'>
          <geometry>
            <mesh>
              <uri>model://my_model/meshes/VisualMesh1.dae</uri>
            </mesh>
          </geometry>
        </visual>
        <collision name='collision'>
          <geometry>
            <mesh>
              <uri>model://my_model/meshes/CollisionMeshCubesNoFloor2.dae</uri>
            </mesh>
          </geometry>
          <max_contacts>20</max_contacts>
          <surface>
            <contact>
              <ode/>
            </contact>
            <bounce/>
            <friction>
              <ode>
                <mu>100</mu>
                <mu2>50</mu2>
              </ode>
              <torsional>
                <ode/>
              </torsional>
            </friction>
          </surface>
        </collision>
        <self_collide>0</self_collide>
        <enable_wind>0</enable_wind>
        <kinematic>0</kinematic>
      </link>
      <pose>16.1761 -12.1276 1 0 -0 0</pose>
    </model>
    <model name='ground_plane'>
      <static>1</static>
      <link name='link'>
        <collision name='collision'>
          <geometry>
            <plane>
              <normal>0 0 1</normal>
              <size>100 100</size>
            </plane>
          </geometry>
          <surface>
            <contact>
              <collide_bitmask>65535</collide_bitmask>
              <ode/>
            </contact>
            <friction>
              <ode>
                <mu>100</mu>
                <mu2>50</mu2>
              </ode>
              <torsional>
                <ode/>
              </torsional>
            </friction>
            <bounce/>
          </surface>
          <max_contacts>20</max_contacts>
        </collision>
        <visual name='visual'>
          <cast_shadows>0</cast_shadows>
          <geometry>
            <plane>
              <normal>0 0 1</normal>
              <size>100 100</size>
            </plane>
          </geometry>
          <material>
            <script>
              <uri>file://media/materials/scripts/gazebo.material</uri>
              <name>Gazebo/Grey</name>
            </script>
          </material>
        </visual>
        <self_collide>0</self_collide>
        <enable_wind>0</enable_wind>
        <kinematic>0</kinematic>
      </link>
      <pose>-5.10672 4.65884 1.27 0 -0 0</pose>
    </model>
    <model name='my_bot'>
      <link name='base_link'>
        <inertial>
          <pose>0 0 0.25 0 -0 0</pose>
          <mass>2</mass>
          <inertia>
            <ixx>0.00416667</ixx>
            <ixy>0</ixy>
            <ixz>0</ixz>
            <iyy>0.0108333</iyy>
            <iyz>0</iyz>
            <izz>0.0141667</izz>
          </inertia>
        </inertial>
        <collision name='base_link_fixed_joint_lump__base_plate_collision'>
          <pose>0 0 0.25 0 -0 0</pose>
          <geometry>
            <box>
              <size>0.25 0.15 0.05</size>
            </box>
          </geometry>
          <max_contacts>10</max_contacts>
          <surface>
            <contact>
              <ode/>
            </contact>
            <bounce/>
            <friction>
              <torsional>
                <ode/>
              </torsional>
              <ode/>
            </friction>
          </surface>
        </collision>
        <visual name='base_link_fixed_joint_lump__base_plate_visual'>
          <pose>0 0 0.25 0 -0 0</pose>
          <geometry>
            <box>
              <size>0.25 0.15 0.05</size>
            </box>
          </geometry>
        </visual>
        <self_collide>0</self_collide>
        <enable_wind>0</enable_wind>
        <kinematic>0</kinematic>
      </link>
      <joint name='fork_wheel_left_joint' type='revolute'>
        <pose relative_to='base_link'>-0.19 0.9 0.0325 3.14159 1.57079 3.14159</pose>
        <parent>base_link</parent>
        <child>fork_wheel_left</child>
        <axis>
          <xyz>0 0 1</xyz>
          <limit>
            <lower>-1e+16</lower>
            <upper>1e+16</upper>
          </limit>
          <dynamics>
            <damping>0.1</damping>
            <friction>0.1</friction>
            <spring_reference>0</spring_reference>
            <spring_stiffness>0</spring_stiffness>
          </dynamics>
        </axis>
      </joint>
      <link name='fork_wheel_left'>
        <pose relative_to='fork_wheel_left_joint'>0 0 0 0 -0 0</pose>
        <inertial>
          <pose>0 0 0 0 -0 0</pose>
          <mass>0.3</mass>
          <inertia>
            <ixx>0.000201719</ixx>
            <ixy>0</ixy>
            <ixz>0</ixz>
            <iyy>0.000201719</iyy>
            <iyz>0</iyz>
            <izz>0.000158437</izz>
          </inertia>
        </inertial>
        <collision name='fork_wheel_left_collision'>
          <pose>0 0 0 0 -0 0</pose>
          <geometry>
            <cylinder>
              <length>0.07</length>
              <radius>0.0325</radius>
            </cylinder>
          </geometry>
          <surface>
            <contact>
              <ode/>
            </contact>
            <friction>
              <ode>
                <mu>0.9</mu>
                <mu2>1</mu2>
              </ode>
              <torsional>
                <ode/>
              </torsional>
            </friction>
            <bounce/>
          </surface>
          <max_contacts>10</max_contacts>
        </collision>
        <visual name='fork_wheel_left_visual'>
          <pose>0 0 0 0 -0 0</pose>
          <geometry>
            <cylinder>
              <length>0.07</length>
              <radius>0.0325</radius>
            </cylinder>
          </geometry>
          <material>
            <script>
              <name>Gazebo/Blue</name>
              <uri>file://media/materials/scripts/gazebo.material</uri>
            </script>
          </material>
        </visual>
        <self_collide>0</self_collide>
        <enable_wind>0</enable_wind>
        <kinematic>0</kinematic>
      </link>
      <joint name='fork_wheel_right_joint' type='revolute'>
        <pose relative_to='base_link'>0.19 0.9 0.0325 3.14159 1.57079 3.14159</pose>
        <parent>base_link</parent>
        <child>fork_wheel_right</child>
        <axis>
          <xyz>0 0 1</xyz>
          <limit>
            <lower>-1e+16</lower>
            <upper>1e+16</upper>
          </limit>
          <dynamics>
            <damping>0.1</damping>
            <friction>0.1</friction>
            <spring_reference>0</spring_reference>
            <spring_stiffness>0</spring_stiffness>
          </dynamics>
        </axis>
      </joint>
      <link name='fork_wheel_right'>
        <pose relative_to='fork_wheel_right_joint'>0 0 0 0 -0 0</pose>
        <inertial>
          <pose>0 0 0 0 -0 0</pose>
          <mass>0.3</mass>
          <inertia>
            <ixx>0.000201719</ixx>
            <ixy>0</ixy>
            <ixz>0</ixz>
            <iyy>0.000201719</iyy>
            <iyz>0</iyz>
            <izz>0.000158437</izz>
          </inertia>
        </inertial>
        <collision name='fork_wheel_right_collision'>
          <pose>0 0 0 0 -0 0</pose>
          <geometry>
            <cylinder>
              <length>0.07</length>
              <radius>0.0325</radius>
            </cylinder>
          </geometry>
          <surface>
            <contact>
              <ode/>
            </contact>
            <friction>
              <ode>
                <mu>0.9</mu>
                <mu2>1</mu2>
              </ode>
              <torsional>
                <ode/>
              </torsional>
            </friction>
            <bounce/>
          </surface>
          <max_contacts>10</max_contacts>
        </collision>
        <visual name='fork_wheel_right_visual'>
          <pose>0 0 0 0 -0 0</pose>
          <geometry>
            <cylinder>
              <length>0.07</length>
              <radius>0.0325</radius>
            </cylinder>
          </geometry>
          <material>
            <script>
              <name>Gazebo/Blue</name>
              <uri>file://media/materials/scripts/gazebo.material</uri>
            </script>
          </material>
        </visual>
        <self_collide>0</self_collide>
        <enable_wind>0</enable_wind>
        <kinematic>0</kinematic>
      </link>
      <joint name='linear_actuator_joint' type='prismatic'>
        <pose relative_to='base_link'>0 0 0.275 0 -0 0</pose>
        <parent>base_link</parent>
        <child>linear_actuator</child>
        <axis>
          <xyz>0 0 1</xyz>
          <limit>
            <lower>0</lower>
            <upper>0.12</upper>
            <effort>100</effort>
            <velocity>0.1</velocity>
          </limit>
          <dynamics>
            <damping>0.1</damping>
            <friction>0.1</friction>
            <spring_reference>0</spring_reference>
            <spring_stiffness>0</spring_stiffness>
          </dynamics>
        </axis>
        <physics>
          <ode>
            <limit>
              <cfm>0</cfm>
              <erp>0.2</erp>
            </limit>
          </ode>
        </physics>
      </joint>
      <link name='linear_actuator'>
        <pose relative_to='linear_actuator_joint'>0 0 0 0 -0 0</pose>
        <inertial>
          <pose>0 0.374799 -0.126418 0 -0 0</pose>
          <mass>42.3</mass>
          <inertia>
            <ixx>3.42238</ixx>
            <ixy>8.65082e-17</ixy>
            <ixz>-2.28344e-17</ixz>
            <iyy>1.65829</iyy>
            <iyz>0.696312</iyz>
            <izz>4.26743</izz>
          </inertia>
        </inertial>
        <collision name='linear_actuator_collision'>
          <pose>0 0 0.05 0 -0 0</pose>
          <geometry>
            <box>
              <size>0.07 0.15 0.1</size>
            </box>
          </geometry>
          <max_contacts>10</max_contacts>
          <surface>
            <contact>
              <ode/>
            </contact>
            <bounce/>
            <friction>
              <torsional>
                <ode/>
              </torsional>
              <ode/>
            </friction>
          </surface>
        </collision>
        <collision name='linear_actuator_fixed_joint_lump__frame_box_collision_1'>
          <pose>0 0.18 -0.075 0 -0 0</pose>
          <geometry>
            <box>
              <size>0.54 0.15 0.3</size>
            </box>
          </geometry>
          <surface>
            <contact>
              <ode/>
            </contact>
            <friction>
              <ode/>
              <torsional>
                <ode/>
              </torsional>
            </friction>
            <bounce/>
          </surface>
          <max_contacts>10</max_contacts>
        </collision>
        <collision name='linear_actuator_fixed_joint_lump__left_fork_collision_2'>
          <pose>-0.19 0.61 -0.2 0 -0 0</pose>
          <geometry>
            <box>
              <size>0.16 0.7 0.05</size>
            </box>
          </geometry>
          <max_contacts>10</max_contacts>
          <surface>
            <contact>
              <ode/>
            </contact>
            <bounce/>
            <friction>
              <torsional>
                <ode/>
              </torsional>
              <ode/>
            </friction>
          </surface>
        </collision>
        <collision name='linear_actuator_fixed_joint_lump__right_fork_collision_3'>
          <pose>0.19 0.61 -0.2 0 -0 0</pose>
          <geometry>
            <box>
              <size>0.16 0.7 0.05</size>
            </box>
          </geometry>
          <max_contacts>10</max_contacts>
          <surface>
            <contact>
              <ode/>
            </contact>
            <bounce/>
            <friction>
              <torsional>
                <ode/>
              </torsional>
              <ode/>
            </friction>
          </surface>
        </collision>
        <visual name='linear_actuator_visual'>
          <pose>0 0 0.05 0 -0 0</pose>
          <geometry>
            <box>
              <size>0.07 0.15 0.1</size>
            </box>
          </geometry>
        </visual>
        <visual name='linear_actuator_fixed_joint_lump__frame_box_visual_1'>
          <pose>0 0.18 -0.075 0 -0 0</pose>
          <geometry>
            <box>
              <size>0.54 0.15 0.3</size>
            </box>
          </geometry>
          <material>
            <script>
              <name>Gazebo/Red</name>
              <uri>file://media/materials/scripts/gazebo.material</uri>
            </script>
          </material>
        </visual>
        <visual name='linear_actuator_fixed_joint_lump__left_fork_visual_2'>
          <pose>-0.19 0.61 -0.2 0 -0 0</pose>
          <geometry>
            <box>
              <size>0.16 0.7 0.05</size>
            </box>
          </geometry>
        </visual>
        <visual name='linear_actuator_fixed_joint_lump__lidar_visual_3'>
          <pose>0 0.18 0.175 0 -0 0</pose>
          <geometry>
            <cylinder>
              <length>0.07</length>
              <radius>0.05</radius>
            </cylinder>
          </geometry>
          <material>
            <script>
              <name>Gazebo/Blue</name>
              <uri>file://media/materials/scripts/gazebo.material</uri>
            </script>
          </material>
        </visual>
        <visual name='linear_actuator_fixed_joint_lump__camera_link_forks_visual_4'>
          <pose>0 0.18 0.275 0 0.18 1.5708</pose>
          <geometry>
            <box>
              <size>0.01 0.03 0.03</size>
            </box>
          </geometry>
          <material>
            <script>
              <name>Gazebo/Black</name>
              <uri>file://media/materials/scripts/gazebo.material</uri>
            </script>
          </material>
        </visual>
        <visual name='linear_actuator_fixed_joint_lump__camera_link_forks_visual_5'>
          <pose>-0 0.171049 0.225808 0 0.18 1.5708</pose>
          <geometry>
            <cylinder>
              <length>0.1</length>
              <radius>0.002</radius>
            </cylinder>
          </geometry>
          <material>
            <script>
              <name>Gazebo/Black</name>
              <uri>file://media/materials/scripts/gazebo.material</uri>
            </script>
          </material>
        </visual>
        <visual name='linear_actuator_fixed_joint_lump__camera_link_steering_visual_6'>
          <pose>0 0.18 0.275 0 0.18 -1.5708</pose>
          <geometry>
            <box>
              <size>0.01 0.03 0.03</size>
            </box>
          </geometry>
          <material>
            <script>
              <name>Gazebo/Black</name>
              <uri>file://media/materials/scripts/gazebo.material</uri>
            </script>
          </material>
        </visual>
        <visual name='linear_actuator_fixed_joint_lump__camera_link_steering_visual_7'>
          <pose>-0 0.188951 0.225808 0 0.18 -1.5708</pose>
          <geometry>
            <cylinder>
              <length>0.1</length>
              <radius>0.002</radius>
            </cylinder>
          </geometry>
          <material>
            <script>
              <name>Gazebo/Black</name>
              <uri>file://media/materials/scripts/gazebo.material</uri>
            </script>
          </material>
        </visual>
        <visual name='linear_actuator_fixed_joint_lump__right_fork_visual_8'>
          <pose>0.19 0.61 -0.2 0 -0 0</pose>
          <geometry>
            <box>
              <size>0.16 0.7 0.05</size>
            </box>
          </geometry>
        </visual>
        <sensor name='lidar' type='ray'>
          <visualize>0</visualize>
          <update_rate>50</update_rate>
          <ray>
            <scan>
              <horizontal>
                <samples>360</samples>
                <min_angle>-3.1415</min_angle>
                <max_angle>3.1415</max_angle>
                <resolution>1</resolution>
              </horizontal>
              <vertical>
                <samples>16</samples>
                <min_angle>-0.261799</min_angle>
                <max_angle>0.261799</max_angle>
              </vertical>
            </scan>
            <range>
              <min>0.1</min>
              <max>100</max>
            </range>
          </ray>
          <plugin name='gazebo_ros' filename='libgazebo_ros_ray_sensor.so'>
            <ros>
              <argument>~/out:=CloudScan</argument>
            </ros>
            <output_type>sensor_msgs/PointCloud2</output_type>
            <frame_name>lidar</frame_name>
          </plugin>
          <pose>0 0.18 0.175 0 -0 0</pose>
        </sensor>
        <sensor name='camera_forks' type='camera'>
          <visualize>1</visualize>
          <update_rate>60</update_rate>
          <camera>
            <horizontal_fov>1.089</horizontal_fov>
            <image>
              <format>R8G8B8</format>
              <width>640</width>
              <height>480</height>
            </image>
            <clip>
              <near>0.05</near>
              <far>60</far>
            </clip>
          </camera>
          <plugin name='camera_controller_fork' filename='libgazebo_ros_camera.so'>
            <frame_name>camera_link_optical_forks</frame_name>
          </plugin>
          <pose>0 0.18 0.275 0 0.18 1.5708</pose>
        </sensor>
        <sensor name='camera_steering' type='camera'>
          <visualize>1</visualize>
          <update_rate>60</update_rate>
          <camera>
            <horizontal_fov>1.089</horizontal_fov>
            <image>
              <format>R8G8B8</format>
              <width>640</width>
              <height>480</height>
            </image>
            <clip>
              <near>0.05</near>
              <far>60</far>
            </clip>
          </camera>
          <plugin name='camera_controller_steering' filename='libgazebo_ros_camera.so'>
            <frame_name>camera_link_optical_steering</frame_name>
          </plugin>
          <pose>0 0.18 0.275 0 0.18 -1.5708</pose>
        </sensor>
        <self_collide>0</self_collide>
        <enable_wind>0</enable_wind>
        <kinematic>0</kinematic>
      </link>
      <joint name='steering_shaft_joint' type='revolute'>
        <pose relative_to='base_link'>0 0 0.225 0 -0 0</pose>
        <parent>base_link</parent>
        <child>steering_shaft</child>
        <axis>
          <xyz>0 0 1</xyz>
          <limit>
            <lower>-1.5708</lower>
            <upper>1.5708</upper>
            <effort>1000</effort>
            <velocity>6.28319</velocity>
          </limit>
          <dynamics>
            <damping>1.1</damping>
            <friction>0.5</friction>
            <spring_reference>0</spring_reference>
            <spring_stiffness>0</spring_stiffness>
          </dynamics>
        </axis>
      </joint>
      <link name='steering_shaft'>
        <pose relative_to='steering_shaft_joint'>0 0 0 0 -0 0</pose>
        <inertial>
          <pose>0 0 0 0 -0 0</pose>
          <mass>0.5</mass>
          <inertia>
            <ixx>0.000729167</ixx>
            <ixy>0</ixy>
            <ixz>0</ixz>
            <iyy>0.000729167</iyy>
            <iyz>0</iyz>
            <izz>0.00015625</izz>
          </inertia>
        </inertial>
        <visual name='steering_shaft_visual'>
          <pose>0 0 -0.0625 0 -0 0</pose>
          <geometry>
            <cylinder>
              <length>0.125</length>
              <radius>0.025</radius>
            </cylinder>
          </geometry>
        </visual>
        <self_collide>0</self_collide>
        <enable_wind>0</enable_wind>
        <kinematic>0</kinematic>
      </link>
      <joint name='steering_wheel_left_joint' type='revolute'>
        <pose relative_to='steering_shaft'>0.11 0 -0.125 3.14159 1.57079 3.14159</pose>
        <parent>steering_shaft</parent>
        <child>steering_wheel_left</child>
        <axis>
          <xyz>0 0 1</xyz>
          <limit>
            <lower>-1e+16</lower>
            <upper>1e+16</upper>
          </limit>
          <dynamics>
            <damping>0.01</damping>
            <friction>0.01</friction>
            <spring_reference>0</spring_reference>
            <spring_stiffness>0</spring_stiffness>
          </dynamics>
        </axis>
      </joint>
      <link name='steering_wheel_left'>
        <pose relative_to='steering_wheel_left_joint'>0 0 0 0 -0 0</pose>
        <inertial>
          <pose>0 0 0 0 -0 0</pose>
          <mass>1.5</mass>
          <inertia>
            <ixx>0.00395</ixx>
            <ixy>0</ixy>
            <ixz>0</ixz>
            <iyy>0.00395</iyy>
            <iyz>0</iyz>
            <izz>0.0075</izz>
          </inertia>
        </inertial>
        <collision name='steering_wheel_left_collision'>
          <pose>0 0 0 0 -0 0</pose>
          <geometry>
            <cylinder>
              <length>0.04</length>
              <radius>0.1</radius>
            </cylinder>
          </geometry>
          <surface>
            <contact>
              <ode/>
            </contact>
            <friction>
              <ode>
                <mu>0.9</mu>
                <mu2>0.9</mu2>
              </ode>
              <torsional>
                <ode/>
              </torsional>
            </friction>
            <bounce/>
          </surface>
          <max_contacts>10</max_contacts>
        </collision>
        <visual name='steering_wheel_left_visual'>
          <pose>0 0 0 0 -0 0</pose>
          <geometry>
            <cylinder>
              <length>0.04</length>
              <radius>0.1</radius>
            </cylinder>
          </geometry>
          <material>
            <script>
              <name>Gazebo/Black</name>
              <uri>file://media/materials/scripts/gazebo.material</uri>
            </script>
          </material>
        </visual>
        <self_collide>0</self_collide>
        <enable_wind>0</enable_wind>
        <kinematic>0</kinematic>
      </link>
      <joint name='steering_wheel_right_joint' type='revolute'>
        <pose relative_to='steering_shaft'>-0.11 0 -0.125 3.14159 1.57079 3.14159</pose>
        <parent>steering_shaft</parent>
        <child>steering_wheel_right</child>
        <axis>
          <xyz>0 0 1</xyz>
          <limit>
            <lower>-1e+16</lower>
            <upper>1e+16</upper>
          </limit>
          <dynamics>
            <damping>0.01</damping>
            <friction>0.01</friction>
            <spring_reference>0</spring_reference>
            <spring_stiffness>0</spring_stiffness>
          </dynamics>
        </axis>
      </joint>
      <link name='steering_wheel_right'>
        <pose relative_to='steering_wheel_right_joint'>0 0 0 0 -0 0</pose>
        <inertial>
          <pose>0 0 0 0 -0 0</pose>
          <mass>1.5</mass>
          <inertia>
            <ixx>0.00395</ixx>
            <ixy>0</ixy>
            <ixz>0</ixz>
            <iyy>0.00395</iyy>
            <iyz>0</iyz>
            <izz>0.0075</izz>
          </inertia>
        </inertial>
        <collision name='steering_wheel_right_collision'>
          <pose>0 0 0 0 -0 0</pose>
          <geometry>
            <cylinder>
              <length>0.04</length>
              <radius>0.1</radius>
            </cylinder>
          </geometry>
          <surface>
            <contact>
              <ode/>
            </contact>
            <friction>
              <ode>
                <mu>0.9</mu>
                <mu2>0.9</mu2>
              </ode>
              <torsional>
                <ode/>
              </torsional>
            </friction>
            <bounce/>
          </surface>
          <max_contacts>10</max_contacts>
        </collision>
        <visual name='steering_wheel_right_visual'>
          <pose>0 0 0 0 -0 0</pose>
          <geometry>
            <cylinder>
              <length>0.04</length>
              <radius>0.1</radius>
            </cylinder>
          </geometry>
          <material>
            <script>
              <name>Gazebo/Black</name>
              <uri>file://media/materials/scripts/gazebo.material</uri>
            </script>
          </material>
        </visual>
        <self_collide>0</self_collide>
        <enable_wind>0</enable_wind>
        <kinematic>0</kinematic>
      </link>
      <static>0</static>
      <plugin name='gazebo_ros2_control' filename='libgazebo_ros2_control.so'>
        <parameters>/home/viktor/Desktop/ros2_ws/install/articubot_one/share/articubot_one/config/my_controllers.yaml</parameters>
        <parameters>/home/viktor/Desktop/ros2_ws/install/articubot_one/share/articubot_one/config/gaz_ros2_ctl_use_sim.yaml</parameters>
      </plugin>
      <pose>0 0 1.3 0 -0 0</pose>
    </model>
  </world>
</sdf>
