<sdf version='1.7'>
  <world name='default'>
    <light name='sun' type='directional'>
      <cast_shadows>1</cast_shadows>
      <pose>0 0 10 0 -0 0</pose>
      <diffuse>0.8 0.8 0.8 1</diffuse>
      <specular>0.2 0.2 0.2 1</specular>
      <attenuation>
        <range>1000</range>
        <constant>0.9</constant>
        <linear>0.01</linear>
        <quadratic>0.001</quadratic>
      </attenuation>
      <direction>-0.5 0.1 -0.9</direction>
      <spot>
        <inner_angle>0</inner_angle>
        <outer_angle>0</outer_angle>
        <falloff>0</falloff>
      </spot>
    </light>
    <gravity>0 0 -9.8</gravity>
    <magnetic_field>6e-06 2.3e-05 -4.2e-05</magnetic_field>
    <atmosphere type='adiabatic'/>
    <physics type='ode'>
      <max_step_size>0.0005</max_step_size>
      <real_time_factor>1</real_time_factor>
      <real_time_update_rate>2000</real_time_update_rate>
    </physics>
    <scene>
      <ambient>1 1 1 1</ambient>
      <background>0.7 0.7 0.7 1</background>
      <shadows>1</shadows>
    </scene>
    <wind/>
    <spherical_coordinates>
      <surface_model>EARTH_WGS84</surface_model>
      <latitude_deg>0</latitude_deg>
      <longitude_deg>0</longitude_deg>
      <elevation>0</elevation>
      <heading_deg>0</heading_deg>
    </spherical_coordinates>
    <state world_name='default'>
      <sim_time>1379 988100000</sim_time>
      <real_time>75 719666048</real_time>
      <wall_time>1727442233 927270215</wall_time>
      <iterations>137637</iterations>
      <model name='ground_plane'>
        <pose>-5.10672 4.65884 1.2 0 -0 0</pose>
        <scale>1 1 1</scale>
        <link name='link'>
          <pose>-5.10672 4.65884 1.2 0 -0 0</pose>
          <velocity>0 0 0 0 -0 0</velocity>
          <acceleration>0 0 0 0 -0 0</acceleration>
          <wrench>0 0 0 0 -0 0</wrench>
        </link>
      </model>
      <model name='my_bot'>
        <pose>4.95452 -2.43623 1.40005 8e-05 -0.000277 1.63837</pose>
        <scale>1 1 1</scale>
        <link name='base_link'>
          <pose>4.95452 -2.43623 1.40005 8e-05 -0.000277 1.63837</pose>
          <velocity>-0.001296 0.008534 -0.001012 0.00494 -0.001169 0.005014</velocity>
          <acceleration>-0.848861 2.79074 -11.7302 -1.12562 -0.619618 -1.84708</acceleration>
          <wrench>-1.69772 5.58148 -23.4605 0 -0 0</wrench>
        </link>
        <link name='fork_wheel_left'>
          <pose>3.81997 -2.70345 1.4326 -1.57042 -0.764455 0.067315</pose>
          <velocity>0.000603 0.002121 -0.002979 0.004487 -0.001171 0.003792</velocity>
          <acceleration>0.991796 6.52846 7.26208 2.11645 -0.77893 -0.285263</acceleration>
          <wrench>0.297539 1.95854 2.17862 0 -0 0</wrench>
        </link>
        <link name='fork_wheel_right'>
          <pose>3.79444 -2.32431 1.43257 1.57062 1.39273 -3.07419</pose>
          <velocity>-0.002897 -0.001276 0.001784 0.036044 -0.044041 0.050445</velocity>
          <acceleration>-21.518 4.6088 -0.693759 -2.84549 -0.863713 -0.384536</acceleration>
          <wrench>-6.4554 1.38264 -0.208128 0 -0 0</wrench>
        </link>
        <link name='linear_actuator'>
          <pose>4.95454 -2.4363 1.67503 -0.000109 -0.000241 1.63837</pose>
          <velocity>-0.001847 0.007017 0.001234 0.0027 -0.00254 0.007182</velocity>
          <acceleration>0.074356 0.432833 2.46842 -1.41947 0.220202 2.06166</acceleration>
          <wrench>3.12294 18.179 103.674 0 -0 0</wrench>
        </link>
        <link name='steering_shaft'>
          <pose>4.95455 -2.43629 1.62505 8.3e-05 -0.000345 1.62416</pose>
          <velocity>-0.001548 0.007451 -0.001047 0.025174 -0.001276 -0.009894</velocity>
          <acceleration>-1.44609 2.44534 -11.5304 2.51065 0.803997 0.269527</acceleration>
          <wrench>-0.723043 1.22267 -5.76521 0 -0 0</wrench>
        </link>
        <link name='steering_wheel_left'>
          <pose>4.9604 -2.54608 1.50007 1.57083 -1.17814 -3.08826</pose>
          <velocity>-0.000407 0.007928 -0.000187 -0.079813 -0.00437 -0.006467</velocity>
          <acceleration>-1.27984 5.49975 -24.2618 1.10851 -1.29837 -3.01792</acceleration>
          <wrench>-1.91976 8.24962 -36.3928 0 -0 0</wrench>
        </link>
        <link name='steering_wheel_right'>
          <pose>4.94867 -2.32641 1.50008 1.57016 -1.18145 -3.08767</pose>
          <velocity>-0.00111 0.013683 0.002323 0.036203 -0.004535 0.015846</velocity>
          <acceleration>-0.385344 24.5587 -16.2368 -0.585224 -0.059573 -0.44969</acceleration>
          <wrench>-0.578016 36.8381 -24.3552 0 -0 0</wrench>
        </link>
      </model>
      <model name='my_model'>
        <pose>4.21367 -1.8557 1 0 -0 0</pose>
        <scale>1 1 1</scale>
        <link name='link'>
          <pose>4.21367 -1.8557 1 0 -0 0</pose>
          <velocity>0 0 0 0 -0 0</velocity>
          <acceleration>0 0 0 0 -0 0</acceleration>
          <wrench>0 0 0 0 -0 0</wrench>
        </link>
      </model>
      <light name='sun'>
        <pose>0 0 10 0 -0 0</pose>
      </light>
    </state>
    <gui fullscreen='0'>
      <camera name='user_camera'>
        <pose>10.3247 -8.3386 2.81357 0 0.060057 2.16108</pose>
        <view_controller>orbit</view_controller>
        <projection_type>perspective</projection_type>
      </camera>
    </gui>
    <model name='my_model'>
      <static>1</static>
      <link name='link'>
        <visual name='visual'>
          <geometry>
            <mesh>
              <uri>model://my_model/meshes/VisualMesh1.dae</uri>
            </mesh>
          </geometry>
        </visual>
        <collision name='collision'>
          <geometry>
            <mesh>
              <uri>model://my_model/meshes/CollisionMesh2.dae</uri>
            </mesh>
          </geometry>
          <max_contacts>20</max_contacts>
          <surface>
            <contact>
              <ode/>
            </contact>
            <bounce/>
            <friction>
              <ode>
                <mu>100</mu>
                <mu2>50</mu2>
              </ode>
              <torsional>
                <ode/>
              </torsional>
            </friction>
          </surface>
        </collision>
        <self_collide>0</self_collide>
        <enable_wind>0</enable_wind>
        <kinematic>0</kinematic>
      </link>
      <pose>16.1761 -12.1276 1 0 -0 0</pose>
    </model>
    <model name='ground_plane'>
      <static>1</static>
      <link name='link'>
        <collision name='collision'>
          <geometry>
            <plane>
              <normal>0 0 1</normal>
              <size>100 100</size>
            </plane>
          </geometry>
          <surface>
            <contact>
              <collide_bitmask>65535</collide_bitmask>
              <ode/>
            </contact>
            <friction>
              <ode>
                <mu>100</mu>
                <mu2>50</mu2>
              </ode>
              <torsional>
                <ode/>
              </torsional>
            </friction>
            <bounce/>
          </surface>
          <max_contacts>10</max_contacts>
        </collision>
        <visual name='visual'>
          <cast_shadows>0</cast_shadows>
          <geometry>
            <plane>
              <normal>0 0 1</normal>
              <size>100 100</size>
            </plane>
          </geometry>
          <material>
            <script>
              <uri>file://media/materials/scripts/gazebo.material</uri>
              <name>Gazebo/Grey</name>
            </script>
          </material>
        </visual>
        <self_collide>0</self_collide>
        <enable_wind>0</enable_wind>
        <kinematic>0</kinematic>
      </link>
      <pose>-5.10672 4.65884 1.2 0 -0 0</pose>
    </model>
    <model name='my_bot'>
      <link name='base_link'>
        <inertial>
          <pose>0 0 0.25 0 -0 0</pose>
          <mass>2</mass>
          <inertia>
            <ixx>0.00416667</ixx>
            <ixy>0</ixy>
            <ixz>0</ixz>
            <iyy>0.0108333</iyy>
            <iyz>0</iyz>
            <izz>0.0141667</izz>
          </inertia>
        </inertial>
        <collision name='base_link_fixed_joint_lump__base_plate_collision'>
          <pose>0 0 0.25 0 -0 0</pose>
          <geometry>
            <box>
              <size>0.25 0.15 0.05</size>
            </box>
          </geometry>
          <max_contacts>10</max_contacts>
          <surface>
            <contact>
              <ode/>
            </contact>
            <bounce/>
            <friction>
              <torsional>
                <ode/>
              </torsional>
              <ode/>
            </friction>
          </surface>
        </collision>
        <visual name='base_link_fixed_joint_lump__base_plate_visual'>
          <pose>0 0 0.25 0 -0 0</pose>
          <geometry>
            <box>
              <size>0.25 0.15 0.05</size>
            </box>
          </geometry>
        </visual>
        <self_collide>0</self_collide>
        <enable_wind>0</enable_wind>
        <kinematic>0</kinematic>
      </link>
      <joint name='fork_wheel_left_joint' type='revolute'>
        <pose relative_to='base_link'>-0.19 1.15 0.0325 3.14159 1.57079 3.14159</pose>
        <parent>base_link</parent>
        <child>fork_wheel_left</child>
        <axis>
          <xyz>0 0 1</xyz>
          <limit>
            <lower>-1e+16</lower>
            <upper>1e+16</upper>
          </limit>
          <dynamics>
            <damping>0.1</damping>
            <friction>0.1</friction>
            <spring_reference>0</spring_reference>
            <spring_stiffness>0</spring_stiffness>
          </dynamics>
        </axis>
      </joint>
      <link name='fork_wheel_left'>
        <pose relative_to='fork_wheel_left_joint'>0 0 0 0 -0 0</pose>
        <inertial>
          <pose>0 0 0 0 -0 0</pose>
          <mass>0.3</mass>
          <inertia>
            <ixx>0.000201719</ixx>
            <ixy>0</ixy>
            <ixz>0</ixz>
            <iyy>0.000201719</iyy>
            <iyz>0</iyz>
            <izz>0.000158437</izz>
          </inertia>
        </inertial>
        <collision name='fork_wheel_left_collision'>
          <pose>0 0 0 0 -0 0</pose>
          <geometry>
            <cylinder>
              <length>0.07</length>
              <radius>0.0325</radius>
            </cylinder>
          </geometry>
          <surface>
            <contact>
              <ode/>
            </contact>
            <friction>
              <ode>
                <mu>0.9</mu>
                <mu2>1</mu2>
              </ode>
              <torsional>
                <ode/>
              </torsional>
            </friction>
            <bounce/>
          </surface>
          <max_contacts>10</max_contacts>
        </collision>
        <visual name='fork_wheel_left_visual'>
          <pose>0 0 0 0 -0 0</pose>
          <geometry>
            <cylinder>
              <length>0.07</length>
              <radius>0.0325</radius>
            </cylinder>
          </geometry>
          <material>
            <script>
              <name>Gazebo/Blue</name>
              <uri>file://media/materials/scripts/gazebo.material</uri>
            </script>
          </material>
        </visual>
        <self_collide>0</self_collide>
        <enable_wind>0</enable_wind>
        <kinematic>0</kinematic>
      </link>
      <joint name='fork_wheel_right_joint' type='revolute'>
        <pose relative_to='base_link'>0.19 1.15 0.0325 3.14159 1.57079 3.14159</pose>
        <parent>base_link</parent>
        <child>fork_wheel_right</child>
        <axis>
          <xyz>0 0 1</xyz>
          <limit>
            <lower>-1e+16</lower>
            <upper>1e+16</upper>
          </limit>
          <dynamics>
            <damping>0.1</damping>
            <friction>0.1</friction>
            <spring_reference>0</spring_reference>
            <spring_stiffness>0</spring_stiffness>
          </dynamics>
        </axis>
      </joint>
      <link name='fork_wheel_right'>
        <pose relative_to='fork_wheel_right_joint'>0 0 0 0 -0 0</pose>
        <inertial>
          <pose>0 0 0 0 -0 0</pose>
          <mass>0.3</mass>
          <inertia>
            <ixx>0.000201719</ixx>
            <ixy>0</ixy>
            <ixz>0</ixz>
            <iyy>0.000201719</iyy>
            <iyz>0</iyz>
            <izz>0.000158437</izz>
          </inertia>
        </inertial>
        <collision name='fork_wheel_right_collision'>
          <pose>0 0 0 0 -0 0</pose>
          <geometry>
            <cylinder>
              <length>0.07</length>
              <radius>0.0325</radius>
            </cylinder>
          </geometry>
          <surface>
            <contact>
              <ode/>
            </contact>
            <friction>
              <ode>
                <mu>0.9</mu>
                <mu2>1</mu2>
              </ode>
              <torsional>
                <ode/>
              </torsional>
            </friction>
            <bounce/>
          </surface>
          <max_contacts>10</max_contacts>
        </collision>
        <visual name='fork_wheel_right_visual'>
          <pose>0 0 0 0 -0 0</pose>
          <geometry>
            <cylinder>
              <length>0.07</length>
              <radius>0.0325</radius>
            </cylinder>
          </geometry>
          <material>
            <script>
              <name>Gazebo/Blue</name>
              <uri>file://media/materials/scripts/gazebo.material</uri>
            </script>
          </material>
        </visual>
        <self_collide>0</self_collide>
        <enable_wind>0</enable_wind>
        <kinematic>0</kinematic>
      </link>
      <joint name='linear_actuator_joint' type='prismatic'>
        <pose relative_to='base_link'>0 0 0.275 0 -0 0</pose>
        <parent>base_link</parent>
        <child>linear_actuator</child>
        <axis>
          <xyz>0 0 1</xyz>
          <limit>
            <lower>0</lower>
            <upper>0.12</upper>
            <effort>5000</effort>
            <velocity>0.07</velocity>
          </limit>
          <dynamics>
            <damping>1</damping>
            <friction>1</friction>
            <spring_reference>0</spring_reference>
            <spring_stiffness>0</spring_stiffness>
          </dynamics>
        </axis>
      </joint>
      <link name='linear_actuator'>
        <pose relative_to='linear_actuator_joint'>0 0 0 0 -0 0</pose>
        <inertial>
          <pose>0 0.37619 -0.12619 0 -0 0</pose>
          <mass>42</mass>
          <inertia>
            <ixx>3.42863</ixx>
            <ixy>4.3563e-17</ixy>
            <ixz>-1.13666e-17</ixz>
            <iyy>1.67601</iyy>
            <iyz>0.71619</iyz>
            <izz>4.25559</izz>
          </inertia>
        </inertial>
        <collision name='linear_actuator_collision'>
          <pose>0 0 0.1 0 -0 0</pose>
          <geometry>
            <box>
              <size>0.07 0.15 0.2</size>
            </box>
          </geometry>
          <max_contacts>10</max_contacts>
          <surface>
            <contact>
              <ode/>
            </contact>
            <bounce/>
            <friction>
              <torsional>
                <ode/>
              </torsional>
              <ode/>
            </friction>
          </surface>
        </collision>
        <collision name='linear_actuator_fixed_joint_lump__frame_box_collision_1'>
          <pose>0 0.18 -0.075 0 -0 0</pose>
          <geometry>
            <box>
              <size>0.54 0.15 0.3</size>
            </box>
          </geometry>
          <surface>
            <contact>
              <ode/>
            </contact>
            <friction>
              <ode/>
              <torsional>
                <ode/>
              </torsional>
            </friction>
            <bounce/>
          </surface>
          <max_contacts>10</max_contacts>
        </collision>
        <collision name='linear_actuator_fixed_joint_lump__left_fork_collision_2'>
          <pose>-0.19 0.61 -0.2 0 -0 0</pose>
          <geometry>
            <box>
              <size>0.16 0.7 0.05</size>
            </box>
          </geometry>
          <max_contacts>10</max_contacts>
          <surface>
            <contact>
              <ode/>
            </contact>
            <bounce/>
            <friction>
              <torsional>
                <ode/>
              </torsional>
              <ode/>
            </friction>
          </surface>
        </collision>
        <collision name='linear_actuator_fixed_joint_lump__right_fork_collision_3'>
          <pose>0.19 0.61 -0.2 0 -0 0</pose>
          <geometry>
            <box>
              <size>0.16 0.7 0.05</size>
            </box>
          </geometry>
          <max_contacts>10</max_contacts>
          <surface>
            <contact>
              <ode/>
            </contact>
            <bounce/>
            <friction>
              <torsional>
                <ode/>
              </torsional>
              <ode/>
            </friction>
          </surface>
        </collision>
        <visual name='linear_actuator_visual'>
          <pose>0 0 0.1 0 -0 0</pose>
          <geometry>
            <box>
              <size>0.07 0.15 0.2</size>
            </box>
          </geometry>
        </visual>
        <visual name='linear_actuator_fixed_joint_lump__frame_box_visual_1'>
          <pose>0 0.18 -0.075 0 -0 0</pose>
          <geometry>
            <box>
              <size>0.54 0.15 0.3</size>
            </box>
          </geometry>
          <material>
            <script>
              <name>Gazebo/Red</name>
              <uri>file://media/materials/scripts/gazebo.material</uri>
            </script>
          </material>
        </visual>
        <visual name='linear_actuator_fixed_joint_lump__left_fork_visual_2'>
          <pose>-0.19 0.61 -0.2 0 -0 0</pose>
          <geometry>
            <box>
              <size>0.16 0.7 0.05</size>
            </box>
          </geometry>
        </visual>
        <visual name='linear_actuator_fixed_joint_lump__right_fork_visual_3'>
          <pose>0.19 0.61 -0.2 0 -0 0</pose>
          <geometry>
            <box>
              <size>0.16 0.7 0.05</size>
            </box>
          </geometry>
        </visual>
        <self_collide>0</self_collide>
        <enable_wind>0</enable_wind>
        <kinematic>0</kinematic>
      </link>
      <joint name='steering_shaft_joint' type='revolute'>
        <pose relative_to='base_link'>0 0 0.225 0 -0 0</pose>
        <parent>base_link</parent>
        <child>steering_shaft</child>
        <axis>
          <xyz>0 0 1</xyz>
          <limit>
            <lower>-1.5708</lower>
            <upper>1.5708</upper>
            <effort>1000</effort>
            <velocity>6.28319</velocity>
          </limit>
          <dynamics>
            <damping>1</damping>
            <friction>0.3</friction>
            <spring_reference>0</spring_reference>
            <spring_stiffness>0</spring_stiffness>
          </dynamics>
        </axis>
      </joint>
      <link name='steering_shaft'>
        <pose relative_to='steering_shaft_joint'>0 0 0 0 -0 0</pose>
        <inertial>
          <pose>0 0 0 0 -0 0</pose>
          <mass>0.5</mass>
          <inertia>
            <ixx>0.000729167</ixx>
            <ixy>0</ixy>
            <ixz>0</ixz>
            <iyy>0.000729167</iyy>
            <iyz>0</iyz>
            <izz>0.00015625</izz>
          </inertia>
        </inertial>
        <visual name='steering_shaft_visual'>
          <pose>0 0 -0.0625 0 -0 0</pose>
          <geometry>
            <cylinder>
              <length>0.125</length>
              <radius>0.025</radius>
            </cylinder>
          </geometry>
        </visual>
        <self_collide>0</self_collide>
        <enable_wind>0</enable_wind>
        <kinematic>0</kinematic>
      </link>
      <joint name='steering_wheel_left_joint' type='revolute'>
        <pose relative_to='steering_shaft'>-0.11 0 -0.125 3.14159 1.57079 3.14159</pose>
        <parent>steering_shaft</parent>
        <child>steering_wheel_left</child>
        <axis>
          <xyz>0 0 1</xyz>
          <limit>
            <effort>1000</effort>
            <velocity>1</velocity>
            <lower>-1e+16</lower>
            <upper>1e+16</upper>
          </limit>
          <dynamics>
            <damping>0.01</damping>
            <friction>0.01</friction>
            <spring_reference>0</spring_reference>
            <spring_stiffness>0</spring_stiffness>
          </dynamics>
        </axis>
      </joint>
      <link name='steering_wheel_left'>
        <pose relative_to='steering_wheel_left_joint'>0 0 0 0 -0 0</pose>
        <inertial>
          <pose>0 0 0 0 -0 0</pose>
          <mass>1.5</mass>
          <inertia>
            <ixx>0.00395</ixx>
            <ixy>0</ixy>
            <ixz>0</ixz>
            <iyy>0.00395</iyy>
            <iyz>0</iyz>
            <izz>0.0075</izz>
          </inertia>
        </inertial>
        <collision name='steering_wheel_left_collision'>
          <pose>0 0 0 0 -0 0</pose>
          <geometry>
            <cylinder>
              <length>0.04</length>
              <radius>0.1</radius>
            </cylinder>
          </geometry>
          <surface>
            <contact>
              <ode/>
            </contact>
            <friction>
              <ode>
                <mu>0.9</mu>
                <mu2>0.9</mu2>
              </ode>
              <torsional>
                <ode/>
              </torsional>
            </friction>
            <bounce/>
          </surface>
          <max_contacts>10</max_contacts>
        </collision>
        <visual name='steering_wheel_left_visual'>
          <pose>0 0 0 0 -0 0</pose>
          <geometry>
            <cylinder>
              <length>0.04</length>
              <radius>0.1</radius>
            </cylinder>
          </geometry>
          <material>
            <script>
              <name>Gazebo/Black</name>
              <uri>file://media/materials/scripts/gazebo.material</uri>
            </script>
          </material>
        </visual>
        <self_collide>0</self_collide>
        <enable_wind>0</enable_wind>
        <kinematic>0</kinematic>
      </link>
      <joint name='steering_wheel_right_joint' type='revolute'>
        <pose relative_to='steering_shaft'>0.11 0 -0.125 3.14159 1.57079 3.14159</pose>
        <parent>steering_shaft</parent>
        <child>steering_wheel_right</child>
        <axis>
          <xyz>0 0 1</xyz>
          <limit>
            <effort>1000</effort>
            <velocity>1</velocity>
            <lower>-1e+16</lower>
            <upper>1e+16</upper>
          </limit>
          <dynamics>
            <damping>0.01</damping>
            <friction>0.01</friction>
            <spring_reference>0</spring_reference>
            <spring_stiffness>0</spring_stiffness>
          </dynamics>
        </axis>
      </joint>
      <link name='steering_wheel_right'>
        <pose relative_to='steering_wheel_right_joint'>0 0 0 0 -0 0</pose>
        <inertial>
          <pose>0 0 0 0 -0 0</pose>
          <mass>1.5</mass>
          <inertia>
            <ixx>0.00395</ixx>
            <ixy>0</ixy>
            <ixz>0</ixz>
            <iyy>0.00395</iyy>
            <iyz>0</iyz>
            <izz>0.0075</izz>
          </inertia>
        </inertial>
        <collision name='steering_wheel_right_collision'>
          <pose>0 0 0 0 -0 0</pose>
          <geometry>
            <cylinder>
              <length>0.04</length>
              <radius>0.1</radius>
            </cylinder>
          </geometry>
          <surface>
            <contact>
              <ode/>
            </contact>
            <friction>
              <ode>
                <mu>0.9</mu>
                <mu2>0.9</mu2>
              </ode>
              <torsional>
                <ode/>
              </torsional>
            </friction>
            <bounce/>
          </surface>
          <max_contacts>10</max_contacts>
        </collision>
        <visual name='steering_wheel_right_visual'>
          <pose>0 0 0 0 -0 0</pose>
          <geometry>
            <cylinder>
              <length>0.04</length>
              <radius>0.1</radius>
            </cylinder>
          </geometry>
          <material>
            <script>
              <name>Gazebo/Black</name>
              <uri>file://media/materials/scripts/gazebo.material</uri>
            </script>
          </material>
        </visual>
        <self_collide>0</self_collide>
        <enable_wind>0</enable_wind>
        <kinematic>0</kinematic>
      </link>
      <static>0</static>
      <plugin name='diff_drive' filename='libgazebo_ros_diff_drive.so'>
        <left_joint>steering_wheel_right_joint</left_joint>
        <right_joint>steering_wheel_left_joint</right_joint>
        <wheel_separation>0.22</wheel_separation>
        <wheel_diameter>0.2</wheel_diameter>
        <max_wheel_torque>28</max_wheel_torque>
        <linear_velocity_limit>0.01</linear_velocity_limit>
        <odometry_frame>odom</odometry_frame>
        <robot_base_frame>base_link</robot_base_frame>
        <publish_odom>1</publish_odom>
        <publish_odom_tf>1</publish_odom_tf>
        <publish_wheel_tf>1</publish_wheel_tf>
      </plugin>
      <pose>0 0 1.5 0 -0 0</pose>
    </model>
  </world>
</sdf>
